Workbook
Name Dashboard_Categories: Dashboard_Lists!$C$2:$C$11
Name Dashboard_Departments: Dashboard_Lists!$B$2:$B$9
Name Dashboard_Months: Dashboard_Lists!$A$2:$A$26

Sheet Dashboard
A1: FIN-W5-005 | FINANCIAL INTELLIGENCE DASHBOARD
A2: Corporate Finance • FP&A • Receivables • Cash Flow • Risk Management
A3: EXPENSE FILTER / SELECTED VALUES
A4: Dropdown for filter | C4: Month | D4: 45474 | F4: Department | G4: All Departments | I4: Category | J4: All Categories
A6: SELECTED MONTH EXPENSE | C6: SELECTED DEPARTMENT EXPENSE | E6: SELECTED CATEGORY EXPENSE | G6: CURRENT FILTERED EXPENSE | I6: Collection Efficiency | K6: Outstanding AR
A7: =IF(D4="All Months",SUM(Clean_Expenses!$E:$E),SUMIFS(Clean_Expenses!$E:$E,Clean_Expenses!$B:$B,">="&D4,Clean_Expenses!$B:$B,"<"&EDATE(D4,1))) -> 924314.79 | C7: =IF(G4="All Departments",SUM(Clean_Expenses!$E:$E),SUMIFS(Clean_Expenses!$E:$E,Clean_Expenses!$C:$C,G4)) -> 22048782 | E7: =IF(J4="All Categories",SUM(Clean_Expenses!$E:$E),SUMIFS(Clean_Expenses!$E:$E,Clean_Expenses!$D:$D,J4)) -> 22048782 | G7: =IF(AND(D4="All Months",G4="All Departments",J4="All Categories"),SUM(Clean_Expenses!$E:$E),SUMIFS(Clean_Expenses!$E:$E,Clean_Expenses!$C:$C,IF(G4="All Departments","<>",G4),Clean_Expenses!$D:$D,IF(J4="All Categories","<>",J4),Clean_Expenses!$B:$B,IF(D4="All Months","<>",">="&D4))) -> 16205859 | I7: =Revenue_Collections!E2 -> 0 | K7: {=IF($D$4="All Months",SUM(Clean_AR_Data!$H:$H),SUMPRODUCT((Clean_AR_Data!$C$2:$C$1642<=EOMONTH($D$4,0))*((Clean_AR_Data!$E$2:$E$1642="")+(Clean_AR_Data!$E$2:$E$1642>EOMONTH($D$4,0))>0)*(Clean_AR_Data!$F$2:$F$1642-IF((Clean_AR_Data!$E$2:$E$1642<>"")*(Clean_AR_Data!$E$2:$E$1642<=EOMONTH($D$4,0)),Clean_AR_Data!$G$2:$G$1642,0))))} -> 7777501.2
A8: Overdue Receivables | D8: Receivable Days | F8: Liquidity Risk Score | H8: Liquidity Risk Level | J8: Revenue collection
A10: =IF($D$4="All Months",SUMPRODUCT((Clean_AR_Data!$D$2:$D$1642<TODAY())*((Clean_AR_Data!$E$2:$E$1642="")+(Clean_AR_Data!$E$2:$E$1642>TODAY())>0)*(Clean_AR_Data!$F$2:$F$1642-IF((Clean_AR_Data!$E$2:$E$1642<>"")*(Clean_AR_Data!$E$2:$E$1642<=TODAY()),Clean_AR_Data!$G$2:$G$1642,0))),SUMPRODUCT((Clean_AR_Data!$C$2:$C$1642<=EOMONTH($D$4,0))*(Clean_AR_Data!$D$2:$D$1642<=EOMONTH($D$4,0))*((Clean_AR_Data!$E$2:$E$1642="")+(Clean_AR_Data!$E$2:$E$1642>EOMONTH($D$4,0))>0)*(Clean_AR_Data!$F$2:$F$1642-IF((Clean_AR_Data!$E$2:$E$1642<>"")*(Clean_AR_Data!$E$2:$E$1642<=EOMONTH($D$4,0)),Clean_AR_Data!$G$2:$G$1642,0)))) -> 4759299.8 | D10: =IF($D$4="All Months",KPI_Summary!$B$2,IFERROR(#REF!/SUMIFS(Revenue_Collections!$B:$B,Revenue_Collections!$A:$A,$D$4)*DAY(EOMONTH($D$4,0)),0)) -> 0 | F10: =IF($D$4="All Months",KPI_Summary!$B$11,MIN(100,ROUND((IF($D$10>90,40,IF($D$10>60,30,IF($D$10>45,20,IF($D$10>30,10,0)))))+(IFERROR(IF($A$10/#REF!>50%,35,IF($A$10/#REF!>30%,25,IF($A$10/#REF!>15%,15,IF($A$10/#REF!>5%,8,0)))),0))+(IFERROR(IF(SUMIFS(Revenue_Collections!$E:$E,Revenue_Collections!$A:$A,$D$4)<50%,25,IF(SUMIFS(Revenue_Collections!$E:$E,Revenue_Collections!$A:$A,$D$4)<70%,18,IF(SUMIFS(Revenue_Collections!$E:$E,Revenue_Collections!$A:$A,$D$4)<85%,10,0))),0)),0))) -> 0 | H10: =IF($F$10>=70,"High",IF($F$10>=40,"Medium","Low")) -> Low | J10: =Revenue_Collections!C3 -> 1498657.4
A27: REVENUE COLLECTION | F27: CASH FORECAST

Sheet Data_Dictionary
A1: Field | B1: Data Type | C1: Business Meaning | D1: Validation / Calculation
A2: Invoice_ID | B2: Text | C2: Unique invoice identifier | D2: Must be unique
A3: Customer_ID | B3: Text | C3: Customer reference | D3: Must exist in Customer_Master
A4: Invoice_Amount | B4: Numeric | C4: Billed revenue | D4: Must be >= 0
A5: Amount_Collected | B5: Numeric | C5: Cash received | D5: Must be <= Invoice_Amount
A6: Due_Date | B6: Date | C6: Payment deadline | D6: Must be >= Invoice_Date
A7: Payment_Date | B7: Date | C7: Actual collection date | D7: Blank when unpaid
A8: Outstanding_Amount | B8: Numeric | C8: Uncollected balance | D8: Invoice_Amount - Amount_Collected
A9: Payment_Delay_Days | B9: Numeric | C9: Days late/early | D9: Payment_Date - Due_Date
A10: Budget | B10: Numeric | C10: Approved spending | D10: Must be >= 0
A11: Actual_Expense | B11: Numeric | C11: Actual spending | D11: Must be >= 0
A12: Variance | B12: Numeric | C12: Budget variance | D12: Actual - Budget
A13: Variance_% | B13: Percentage | C13: Relative budget variance | D13: (Actual-Budget)/Budget

Sheet Clean_AR_Data
A1: Invoice_ID | B1: Customer_ID | C1: Invoice_Date | D1: Due_Date | E1: Payment_Date | F1: Invoice_Amount | G1: Amount_Collected | H1: Outstanding_Amount | I1: Payment_Delay_Days | J1: Payment_Status | K1: Age_Days | L1: Age_Bucket | M1: Invoice_Month | N1: Collection_Month
A2: INV-100001 | B2: CUST-036 | C2: 45301 | D2: 45331 | E2: 45331 | F2: 41621.69 | G2: 41621.69 | H2: =MAX(0,F2-G2) -> 0 | I2: =IF(E2="","",MAX(0,E2-D2)) -> 0 | J2: =IF(H2=0,"Paid",IF(D2<TODAY(),"Overdue","Open")) -> Paid | K2: =IF(H2=0,0,MAX(0,TODAY()-D2)) -> 0 | L2: =IF(H2=0,"Paid",IF(K2<=30,"0-30 Days",IF(K2<=60,"31-60 Days",IF(K2<=90,"61-90 Days",IF(K2<=120,"91-120 Days","120+ Days"))))) -> Paid | M2: 45292 | N2: 45323
A3: INV-100002 | B3: CUST-006 | C3: 45314 | D3: 45344 | F3: 15198.08 | G3: 0 | H3: =MAX(0,F3-G3) -> 15198.08 | I3: =IF(E3="","",MAX(0,E3-D3)) | J3: =IF(H3=0,"Paid",IF(D3<TODAY(),"Overdue","Open")) -> Overdue | K3: =IF(H3=0,0,MAX(0,TODAY()-D3)) -> 912 | L3: =IF(H3=0,"Paid",IF(K3<=30,"0-30 Days",IF(K3<=60,"31-60 Days",IF(K3<=90,"61-90 Days",IF(K3<=120,"91-120 Days","120+ Days"))))) -> 120+ Days | M3: 45292
A4: INV-100003 | B4: CUST-039 | C4: 45295 | D4: 45325 | E4: 45333 | F4: 44550.46 | G4: 44550.46 | H4: =MAX(0,F4-G4) -> 0 | I4: =IF(E4="","",MAX(0,E4-D4)) -> 8 | J4: =IF(H4=0,"Paid",IF(D4<TODAY(),"Overdue","Open")) -> Paid | K4: =IF(H4=0,0,MAX(0,TODAY()-D4)) -> 0 | L4: =IF(H4=0,"Paid",IF(K4<=30,"0-30 Days",IF(K4<=60,"31-60 Days",IF(K4<=90,"61-90 Days",IF(K4<=120,"91-120 Days","120+ Days"))))) -> Paid | M4: 45292 | N4: 45323
A5: INV-100004 | B5: CUST-038 | C5: 45299 | D5: 45329 | F5: 65545.95 | G5: 0 | H5: =MAX(0,F5-G5) -> 65545.95 | I5: =IF(E5="","",MAX(0,E5-D5)) | J5: =IF(H5=0,"Paid",IF(D5<TODAY(),"Overdue","Open")) -> Overdue | K5: =IF(H5=0,0,MAX(0,TODAY()-D5)) -> 927 | L5: =IF(H5=0,"Paid",IF(K5<=30,"0-30 Days",IF(K5<=60,"31-60 Days",IF(K5<=90,"61-90 Days",IF(K5<=120,"91-120 Days","120+ Days"))))) -> 120+ Days | M5: 45292
A6: INV-100005 | B6: CUST-006 | C6: 45318 | D6: 45348 | F6: 22453.14 | G6: 0 | H6: =MAX(0,F6-G6) -> 22453.14 | I6: =IF(E6="","",MAX(0,E6-D6)) | J6: =IF(H6=0,"Paid",IF(D6<TODAY(),"Overdue","Open")) -> Overdue | K6: =IF(H6=0,0,MAX(0,TODAY()-D6)) -> 908 | L6: =IF(H6=0,"Paid",IF(K6<=30,"0-30 Days",IF(K6<=60,"31-60 Days",IF(K6<=90,"61-90 Days",IF(K6<=120,"91-120 Days","120+ Days"))))) -> 120+ Days | M6: 45292
A7: INV-100006 | B7: CUST-046 | C7: 45298 | D7: 45328 | F7: 123088.43 | G7: 0 | H7: =MAX(0,F7-G7) -> 123088.43 | I7: =IF(E7="","",MAX(0,E7-D7)) | J7: =IF(H7=0,"Paid",IF(D7<TODAY(),"Overdue","Open")) -> Overdue | K7: =IF(H7=0,0,MAX(0,TODAY()-D7)) -> 928 | L7: =IF(H7=0,"Paid",IF(K7<=30,"0-30 Days",IF(K7<=60,"31-60 Days",IF(K7<=90,"61-90 Days",IF(K7<=120,"91-120 Days","120+ Days"))))) -> 120+ Days | M7: 45292
A8: INV-100007 | B8: CUST-025 | C8: 45304 | D8: 45334 | F8: 23234.42 | G8: 0 | H8: =MAX(0,F8-G8) -> 23234.42 | I8: =IF(E8="","",MAX(0,E8-D8)) | J8: =IF(H8=0,"Paid",IF(D8<TODAY(),"Overdue","Open")) -> Overdue | K8: =IF(H8=0,0,MAX(0,TODAY()-D8)) -> 922 | L8: =IF(H8=0,"Paid",IF(K8<=30,"0-30 Days",IF(K8<=60,"31-60 Days",IF(K8<=90,"61-90 Days",IF(K8<=120,"91-120 Days","120+ Days"))))) -> 120+ Days | M8: 45292
A9: INV-100008 | B9: CUST-048 | C9: 45313 | D9: 45343 | E9: 45349 | F9: 47179.89 | G9: 47179.89 | H9: =MAX(0,F9-G9) -> 0 | I9: =IF(E9="","",MAX(0,E9-D9)) -> 6 | J9: =IF(H9=0,"Paid",IF(D9<TODAY(),"Overdue","Open")) -> Paid | K9: =IF(H9=0,0,MAX(0,TODAY()-D9)) -> 0 | L9: =IF(H9=0,"Paid",IF(K9<=30,"0-30 Days",IF(K9<=60,"31-60 Days",IF(K9<=90,"61-90 Days",IF(K9<=120,"91-120 Days","120+ Days"))))) -> Paid | M9: 45292 | N9: 45323
A10: INV-100009 | B10: CUST-003 | C10: 45318 | D10: 45348 | E10: 45357 | F10: 48792.88 | G10: 48792.88 | H10: =MAX(0,F10-G10) -> 0 | I10: =IF(E10="","",MAX(0,E10-D10)) -> 9 | J10: =IF(H10=0,"Paid",IF(D10<TODAY(),"Overdue","Open")) -> Paid | K10: =IF(H10=0,0,MAX(0,TODAY()-D10)) -> 0 | L10: =IF(H10=0,"Paid",IF(K10<=30,"0-30 Days",IF(K10<=60,"31-60 Days",IF(K10<=90,"61-90 Days",IF(K10<=120,"91-120 Days","120+ Days"))))) -> Paid | M10: 45292 | N10: 45352
A11: INV-100010 | B11: CUST-011 | C11: 45317 | D11: 45347 | F11: 18904.1 | G11: 0 | H11: =MAX(0,F11-G11) -> 18904.1 | I11: =IF(E11="","",MAX(0,E11-D11)) | J11: =IF(H11=0,"Paid",IF(D11<TODAY(),"Overdue","Open")) -> Overdue | K11: =IF(H11=0,0,MAX(0,TODAY()-D11)) -> 909 | L11: =IF(H11=0,"Paid",IF(K11<=30,"0-30 Days",IF(K11<=60,"31-60 Days",IF(K11<=90,"61-90 Days",IF(K11<=120,"91-120 Days","120+ Days"))))) -> 120+ Days | M11: 45292
A12: INV-100011 | B12: CUST-030 | C12: 45294 | D12: 45324 | F12: 41689.12 | G12: 0 | H12: =MAX(0,F12-G12) -> 41689.12 | I12: =IF(E12="","",MAX(0,E12-D12)) | J12: =IF(H12=0,"Paid",IF(D12<TODAY(),"Overdue","Open")) -> Overdue | K12: =IF(H12=0,0,MAX(0,TODAY()-D12)) -> 932 | L12: =IF(H12=0,"Paid",IF(K12<=30,"0-30 Days",IF(K12<=60,"31-60 Days",IF(K12<=90,"61-90 Days",IF(K12<=120,"91-120 Days","120+ Days"))))) -> 120+ Days | M12: 45292
A13: INV-100012 | B13: CUST-012 | C13: 45312 | D13: 45342 | E13: 45410 | F13: 44676.57 | G13: 44676.57 | H13: =MAX(0,F13-G13) -> 0 | I13: =IF(E13="","",MAX(0,E13-D13)) -> 68 | J13: =IF(H13=0,"Paid",IF(D13<TODAY(),"Overdue","Open")) -> Paid | K13: =IF(H13=0,0,MAX(0,TODAY()-D13)) -> 0 | L13: =IF(H13=0,"Paid",IF(K13<=30,"0-30 Days",IF(K13<=60,"31-60 Days",IF(K13<=90,"61-90 Days",IF(K13<=120,"91-120 Days","120+ Days"))))) -> Paid | M13: 45292 | N13: 45383
A14: INV-100013 | B14: CUST-020 | C14: 45301 | D14: 45331 | E14: 45382 | F14: 70154.75 | G14: 70154.75 | H14: =MAX(0,F14-G14) -> 0 | I14: =IF(E14="","",MAX(0,E14-D14)) -> 51 | J14: =IF(H14=0,"Paid",IF(D14<TODAY(),"Overdue","Open")) -> Paid | K14: =IF(H14=0,0,MAX(0,TODAY()-D14)) -> 0 | L14: =IF(H14=0,"Paid",IF(K14<=30,"0-30 Days",IF(K14<=60,"31-60 Days",IF(K14<=90,"61-90 Days",IF(K14<=120,"91-120 Days","120+ Days"))))) -> Paid | M14: 45292 | N14: 45352
A15: INV-100014 | B15: CUST-040 | C15: 45309 | D15: 45339 | F15: 42225.47 | G15: 0 | H15: =MAX(0,F15-G15) -> 42225.47 | I15: =IF(E15="","",MAX(0,E15-D15)) | J15: =IF(H15=0,"Paid",IF(D15<TODAY(),"Overdue","Open")) -> Overdue | K15: =IF(H15=0,0,MAX(0,TODAY()-D15)) -> 917 | L15: =IF(H15=0,"Paid",IF(K15<=30,"0-30 Days",IF(K15<=60,"31-60 Days",IF(K15<=90,"61-90 Days",IF(K15<=120,"91-120 Days","120+ Days"))))) -> 120+ Days | M15: 45292
A16: INV-100015 | B16: CUST-009 | C16: 45317 | D16: 45347 | E16: 45351 | F16: 94656.55 | G16: 94656.55 | H16: =MAX(0,F16-G16) -> 0 | I16: =IF(E16="","",MAX(0,E16-D16)) -> 4 | J16: =IF(H16=0,"Paid",IF(D16<TODAY(),"Overdue","Open")) -> Paid | K16: =IF(H16=0,0,MAX(0,TODAY()-D16)) -> 0 | L16: =IF(H16=0,"Paid",IF(K16<=30,"0-30 Days",IF(K16<=60,"31-60 Days",IF(K16<=90,"61-90 Days",IF(K16<=120,"91-120 Days","120+ Days"))))) -> Paid | M16: 45292 | N16: 45323
A17: INV-100016 | B17: CUST-041 | C17: 45298 | D17: 45328 | E17: 45328 | F17: 30922.74 | G17: 30922.74 | H17: =MAX(0,F17-G17) -> 0 | I17: =IF(E17="","",MAX(0,E17-D17)) -> 0 | J17: =IF(H17=0,"Paid",IF(D17<TODAY(),"Overdue","Open")) -> Paid | K17: =IF(H17=0,0,MAX(0,TODAY()-D17)) -> 0 | L17: =IF(H17=0,"Paid",IF(K17<=30,"0-30 Days",IF(K17<=60,"31-60 Days",IF(K17<=90,"61-90 Days",IF(K17<=120,"91-120 Days","120+ Days"))))) -> Paid | M17: 45292 | N17: 45323
A18: INV-100017 | B18: CUST-007 | C18: 45299 | D18: 45329 | F18: 54384.24 | G18: 0 | H18: =MAX(0,F18-G18) -> 54384.24 | I18: =IF(E18="","",MAX(0,E18-D18)) | J18: =IF(H18=0,"Paid",IF(D18<TODAY(),"Overdue","Open")) -> Overdue | K18: =IF(H18=0,0,MAX(0,TODAY()-D18)) -> 927 | L18: =IF(H18=0,"Paid",IF(K18<=30,"0-30 Days",IF(K18<=60,"31-60 Days",IF(K18<=90,"61-90 Days",IF(K18<=120,"91-120 Days","120+ Days"))))) -> 120+ Days | M18: 45292
A19: INV-100018 | B19: CUST-011 | C19: 45300 | D19: 45330 | E19: 45342 | F19: 38070.04 | G19: 38070.04 | H19: =MAX(0,F19-G19) -> 0 | I19: =IF(E19="","",MAX(0,E19-D19)) -> 12 | J19: =IF(H19=0,"Paid",IF(D19<TODAY(),"Overdue","Open")) -> Paid | K19: =IF(H19=0,0,MAX(0,TODAY()-D19)) -> 0 | L19: =IF(H19=0,"Paid",IF(K19<=30,"0-30 Days",IF(K19<=60,"31-60 Days",IF(K19<=90,"61-90 Days",IF(K19<=120,"91-120 Days","120+ Days"))))) -> Paid | M19: 45292 | N19: 45323
A20: INV-100019 | B20: CUST-036 | C20: 45296 | D20: 45326 | E20: 45326 | F20: 40127.68 | G20: 40127.68 | H20: =MAX(0,F20-G20) -> 0 | I20: =IF(E20="","",MAX(0,E20-D20)) -> 0 | J20: =IF(H20=0,"Paid",IF(D20<TODAY(),"Overdue","Open")) -> Paid | K20: =IF(H20=0,0,MAX(0,TODAY()-D20)) -> 0 | L20: =IF(H20=0,"Paid",IF(K20<=30,"0-30 Days",IF(K20<=60,"31-60 Days",IF(K20<=90,"61-90 Days",IF(K20<=120,"91-120 Days","120+ Days"))))) -> Paid | M20: 45292 | N20: 45323
A21: INV-100020 | B21: CUST-048 | C21: 45298 | D21: 45328 | E21: 45328 | F21: 37168.05 | G21: 37168.05 | H21: =MAX(0,F21-G21) -> 0 | I21: =IF(E21="","",MAX(0,E21-D21)) -> 0 | J21: =IF(H21=0,"Paid",IF(D21<TODAY(),"Overdue","Open")) -> Paid | K21: =IF(H21=0,0,MAX(0,TODAY()-D21)) -> 0 | L21: =IF(H21=0,"Paid",IF(K21<=30,"0-30 Days",IF(K21<=60,"31-60 Days",IF(K21<=90,"61-90 Days",IF(K21<=120,"91-120 Days","120+ Days"))))) -> Paid | M21: 45292 | N21: 45323
A22: INV-100021 | B22: CUST-011 | C22: 45303 | D22: 45333 | E22: 45333 | F22: 31768.55 | G22: 31768.55 | H22: =MAX(0,F22-G22) -> 0 | I22: =IF(E22="","",MAX(0,E22-D22)) -> 0 | J22: =IF(H22=0,"Paid",IF(D22<TODAY(),"Overdue","Open")) -> Paid | K22: =IF(H22=0,0,MAX(0,TODAY()-D22)) -> 0 | L22: =IF(H22=0,"Paid",IF(K22<=30,"0-30 Days",IF(K22<=60,"31-60 Days",IF(K22<=90,"61-90 Days",IF(K22<=120,"91-120 Days","120+ Days"))))) -> Paid | M22: 45292 | N22: 45323
A23: INV-100022 | B23: CUST-018 | C23: 45297 | D23: 45327 | E23: 45341 | F23: 38826.07 | G23: 38826.07 | H23: =MAX(0,F23-G23) -> 0 | I23: =IF(E23="","",MAX(0,E23-D23)) -> 14 | J23: =IF(H23=0,"Paid",IF(D23<TODAY(),"Overdue","Open")) -> Paid | K23: =IF(H23=0,0,MAX(0,TODAY()-D23)) -> 0 | L23: =IF(H23=0,"Paid",IF(K23<=30,"0-30 Days",IF(K23<=60,"31-60 Days",IF(K23<=90,"61-90 Days",IF(K23<=120,"91-120 Days","120+ Days"))))) -> Paid | M23: 45292 | N23: 45323
A24: INV-100023 | B24: CUST-056 | C24: 45294 | D24: 45324 | E24: 45360 | F24: 31881.46 | G24: 31881.46 | H24: =MAX(0,F24-G24) -> 0 | I24: =IF(E24="","",MAX(0,E24-D24)) -> 36 | J24: =IF(H24=0,"Paid",IF(D24<TODAY(),"Overdue","Open")) -> Paid | K24: =IF(H24=0,0,MAX(0,TODAY()-D24)) -> 0 | L24: =IF(H24=0,"Paid",IF(K24<=30,"0-30 Days",IF(K24<=60,"31-60 Days",IF(K24<=90,"61-90 Days",IF(K24<=120,"91-120 Days","120+ Days"))))) -> Paid | M24: 45292 | N24: 45352
A25: INV-100024 | B25: CUST-060 | C25: 45302 | D25: 45332 | E25: 45332 | F25: 79663.67 | G25: 79663.67 | H25: =MAX(0,F25-G25) -> 0 | I25: =IF(E25="","",MAX(0,E25-D25)) -> 0 | J25: =IF(H25=0,"Paid",IF(D25<TODAY(),"Overdue","Open")) -> Paid | K25: =IF(H25=0,0,MAX(0,TODAY()-D25)) -> 0 | L25: =IF(H25=0,"Paid",IF(K25<=30,"0-30 Days",IF(K25<=60,"31-60 Days",IF(K25<=90,"61-90 Days",IF(K25<=120,"91-120 Days","120+ Days"))))) -> Paid | M25: 45292 | N25: 45323
A26: INV-100025 | B26: CUST-035 | C26: 45305 | D26: 45335 | E26: 45335 | F26: 43624.46 | G26: 43624.46 | H26: =MAX(0,F26-G26) -> 0 | I26: =IF(E26="","",MAX(0,E26-D26)) -> 0 | J26: =IF(H26=0,"Paid",IF(D26<TODAY(),"Overdue","Open")) -> Paid | K26: =IF(H26=0,0,MAX(0,TODAY()-D26)) -> 0 | L26: =IF(H26=0,"Paid",IF(K26<=30,"0-30 Days",IF(K26<=60,"31-60 Days",IF(K26<=90,"61-90 Days",IF(K26<=120,"91-120 Days","120+ Days"))))) -> Paid | M26: 45292 | N26: 45323
A27: INV-100026 | B27: CUST-027 | C27: 45292 | D27: 45322 | E27: 45366 | F27: 40125.58 | G27: 40125.58 | H27: =MAX(0,F27-G27) -> 0 | I27: =IF(E27="","",MAX(0,E27-D27)) -> 44 | J27: =IF(H27=0,"Paid",IF(D27<TODAY(),"Overdue","Open")) -> Paid | K27: =IF(H27=0,0,MAX(0,TODAY()-D27)) -> 0 | L27: =IF(H27=0,"Paid",IF(K27<=30,"0-30 Days",IF(K27<=60,"31-60 Days",IF(K27<=90,"61-90 Days",IF(K27<=120,"91-120 Days","120+ Days"))))) -> Paid | M27: 45292 | N27: 45352
A28: INV-100027 | B28: CUST-021 | C28: 45296 | D28: 45326 | F28: 23878.08 | G28: 0 | H28: =MAX(0,F28-G28) -> 23878.08 | I28: =IF(E28="","",MAX(0,E28-D28)) | J28: =IF(H28=0,"Paid",IF(D28<TODAY(),"Overdue","Open")) -> Overdue | K28: =IF(H28=0,0,MAX(0,TODAY()-D28)) -> 930 | L28: =IF(H28=0,"Paid",IF(K28<=30,"0-30 Days",IF(K28<=60,"31-60 Days",IF(K28<=90,"61-90 Days",IF(K28<=120,"91-120 Days","120+ Days"))))) -> 120+ Days | M28: 45292
A29: INV-100028 | B29: CUST-037 | C29: 45308 | D29: 45338 | E29: 45349 | F29: 17070.5 | G29: 17070.5 | H29: =MAX(0,F29-G29) -> 0 | I29: =IF(E29="","",MAX(0,E29-D29)) -> 11 | J29: =IF(H29=0,"Paid",IF(D29<TODAY(),"Overdue","Open")) -> Paid | K29: =IF(H29=0,0,MAX(0,TODAY()-D29)) -> 0 | L29: =IF(H29=0,"Paid",IF(K29<=30,"0-30 Days",IF(K29<=60,"31-60 Days",IF(K29<=90,"61-90 Days",IF(K29<=120,"91-120 Days","120+ Days"))))) -> Paid | M29: 45292 | N29: 45323
A30: INV-100029 | B30: CUST-036 | C30: 45309 | D30: 45339 | E30: 45354 | F30: 25565.62 | G30: 18829.02 | H30: =MAX(0,F30-G30) -> 6736.6 | I30: =IF(E30="","",MAX(0,E30-D30)) -> 15 | J30: =IF(H30=0,"Paid",IF(D30<TODAY(),"Overdue","Open")) -> Overdue | K30: =IF(H30=0,0,MAX(0,TODAY()-D30)) -> 917 | L30: =IF(H30=0,"Paid",IF(K30<=30,"0-30 Days",IF(K30<=60,"31-60 Days",IF(K30<=90,"61-90 Days",IF(K30<=120,"91-120 Days","120+ Days"))))) -> 120+ Days | M30: 45292 | N30: 45352
A31: INV-100030 | B31: CUST-018 | C31: 45294 | D31: 45324 | E31: 45324 | F31: 34910.18 | G31: 34910.18 | H31: =MAX(0,F31-G31) -> 0 | I31: =IF(E31="","",MAX(0,E31-D31)) -> 0 | J31: =IF(H31=0,"Paid",IF(D31<TODAY(),"Overdue","Open")) -> Paid | K31: =IF(H31=0,0,MAX(0,TODAY()-D31)) -> 0 | L31: =IF(H31=0,"Paid",IF(K31<=30,"0-30 Days",IF(K31<=60,"31-60 Days",IF(K31<=90,"61-90 Days",IF(K31<=120,"91-120 Days","120+ Days"))))) -> Paid | M31: 45292 | N31: 45323
A32: INV-100031 | B32: CUST-002 | C32: 45295 | D32: 45325 | E32: 45325 | F32: 70836.06 | G32: 70836.06 | H32: =MAX(0,F32-G32) -> 0 | I32: =IF(E32="","",MAX(0,E32-D32)) -> 0 | J32: =IF(H32=0,"Paid",IF(D32<TODAY(),"Overdue","Open")) -> Paid | K32: =IF(H32=0,0,MAX(0,TODAY()-D32)) -> 0 | L32: =IF(H32=0,"Paid",IF(K32<=30,"0-30 Days",IF(K32<=60,"31-60 Days",IF(K32<=90,"61-90 Days",IF(K32<=120,"91-120 Days","120+ Days"))))) -> Paid | M32: 45292 | N32: 45323
A33: INV-100032 | B33: CUST-010 | C33: 45302 | D33: 45332 | E33: 45332 | F33: 17036.7 | G33: 17036.7 | H33: =MAX(0,F33-G33) -> 0 | I33: =IF(E33="","",MAX(0,E33-D33)) -> 0 | J33: =IF(H33=0,"Paid",IF(D33<TODAY(),"Overdue","Open")) -> Paid | K33: =IF(H33=0,0,MAX(0,TODAY()-D33)) -> 0 | L33: =IF(H33=0,"Paid",IF(K33<=30,"0-30 Days",IF(K33<=60,"31-60 Days",IF(K33<=90,"61-90 Days",IF(K33<=120,"91-120 Days","120+ Days"))))) -> Paid | M33: 45292 | N33: 45323
A34: INV-100033 | B34: CUST-058 | C34: 45318 | D34: 45348 | E34: 45348 | F34: 104851.72 | G34: 104851.72 | H34: =MAX(0,F34-G34) -> 0 | I34: =IF(E34="","",MAX(0,E34-D34)) -> 0 | J34: =IF(H34=0,"Paid",IF(D34<TODAY(),"Overdue","Open")) -> Paid | K34: =IF(H34=0,0,MAX(0,TODAY()-D34)) -> 0 | L34: =IF(H34=0,"Paid",IF(K34<=30,"0-30 Days",IF(K34<=60,"31-60 Days",IF(K34<=90,"61-90 Days",IF(K34<=120,"91-120 Days","120+ Days"))))) -> Paid | M34: 45292 | N34: 45323
A35: INV-100034 | B35: CUST-026 | C35: 45312 | D35: 45342 | E35: 45351 | F35: 31177.85 | G35: 15147.69 | H35: =MAX(0,F35-G35) -> 16030.16 | I35: =IF(E35="","",MAX(0,E35-D35)) -> 9 | J35: =IF(H35=0,"Paid",IF(D35<TODAY(),"Overdue","Open")) -> Overdue | K35: =IF(H35=0,0,MAX(0,TODAY()-D35)) -> 914 | L35: =IF(H35=0,"Paid",IF(K35<=30,"0-30 Days",IF(K35<=60,"31-60 Days",IF(K35<=90,"61-90 Days",IF(K35<=120,"91-120 Days","120+ Days"))))) -> 120+ Days | M35: 45292 | N35: 45323
A36: INV-100035 | B36: CUST-029 | C36: 45300 | D36: 45330 | F36: 33359.48 | G36: 0 | H36: =MAX(0,F36-G36) -> 33359.48 | I36: =IF(E36="","",MAX(0,E36-D36)) | J36: =IF(H36=0,"Paid",IF(D36<TODAY(),"Overdue","Open")) -> Overdue | K36: =IF(H36=0,0,MAX(0,TODAY()-D36)) -> 926 | L36: =IF(H36=0,"Paid",IF(K36<=30,"0-30 Days",IF(K36<=60,"31-60 Days",IF(K36<=90,"61-90 Days",IF(K36<=120,"91-120 Days","120+ Days"))))) -> 120+ Days | M36: 45292
A37: INV-100036 | B37: CUST-029 | C37: 45300 | D37: 45330 | E37: 45334 | F37: 48490.41 | G37: 48490.41 | H37: =MAX(0,F37-G37) -> 0 | I37: =IF(E37="","",MAX(0,E37-D37)) -> 4 | J37: =IF(H37=0,"Paid",IF(D37<TODAY(),"Overdue","Open")) -> Paid | K37: =IF(H37=0,0,MAX(0,TODAY()-D37)) -> 0 | L37: =IF(H37=0,"Paid",IF(K37<=30,"0-30 Days",IF(K37<=60,"31-60 Days",IF(K37<=90,"61-90 Days",IF(K37<=120,"91-120 Days","120+ Days"))))) -> Paid | M37: 45292 | N37: 45323
A38: INV-100037 | B38: CUST-047 | C38: 45304 | D38: 45334 | E38: 45408 | F38: 33490.08 | G38: 25785.26 | H38: =MAX(0,F38-G38) -> 7704.82 | I38: =IF(E38="","",MAX(0,E38-D38)) -> 74 | J38: =IF(H38=0,"Paid",IF(D38<TODAY(),"Overdue","Open")) -> Overdue | K38: =IF(H38=0,0,MAX(0,TODAY()-D38)) -> 922 | L38: =IF(H38=0,"Paid",IF(K38<=30,"0-30 Days",IF(K38<=60,"31-60 Days",IF(K38<=90,"61-90 Days",IF(K38<=120,"91-120 Days","120+ Days"))))) -> 120+ Days | M38: 45292 | N38: 45383
A39: INV-100038 | B39: CUST-004 | C39: 45295 | D39: 45325 | E39: 45368 | F39: 28129.38 | G39: 28129.38 | H39: =MAX(0,F39-G39) -> 0 | I39: =IF(E39="","",MAX(0,E39-D39)) -> 43 | J39: =IF(H39=0,"Paid",IF(D39<TODAY(),"Overdue","Open")) -> Paid | K39: =IF(H39=0,0,MAX(0,TODAY()-D39)) -> 0 | L39: =IF(H39=0,"Paid",IF(K39<=30,"0-30 Days",IF(K39<=60,"31-60 Days",IF(K39<=90,"61-90 Days",IF(K39<=120,"91-120 Days","120+ Days"))))) -> Paid | M39: 45292 | N39: 45352
A40: INV-100039 | B40: CUST-005 | C40: 45313 | D40: 45343 | E40: 45350 | F40: 46326.34 | G40: 46326.34 | H40: =MAX(0,F40-G40) -> 0 | I40: =IF(E40="","",MAX(0,E40-D40)) -> 7 | J40: =IF(H40=0,"Paid",IF(D40<TODAY(),"Overdue","Open")) -> Paid | K40: =IF(H40=0,0,MAX(0,TODAY()-D40)) -> 0 | L40: =IF(H40=0,"Paid",IF(K40<=30,"0-30 Days",IF(K40<=60,"31-60 Days",IF(K40<=90,"61-90 Days",IF(K40<=120,"91-120 Days","120+ Days"))))) -> Paid | M40: 45292 | N40: 45323
...

Sheet Clean_Expenses
A1: Expense_ID | B1: Expense_Date | C1: Department | D1: Category | E1: Actual_Expense | F1: Vendor_ID
A2: EXP-500001 | B2: 45292 | C2: IT | D2: Salaries | E2: 95356.73 | F2: VEND-121
A3: EXP-500002 | B3: 45301 | C3: IT | D3: Rent | E3: 23332.26 | F3: VEND-121
A4: EXP-500003 | B4: 45292 | C4: IT | D4: Utilities | E4: 8620.85 | F4: VEND-134
A5: EXP-500004 | B5: 45297 | C5: IT | D5: Software | E5: 13851.81 | F5: VEND-172
A6: EXP-500005 | B6: 45306 | C6: IT | D6: Marketing | E6: 17657.69 | F6: VEND-146
A7: EXP-500006 | B7: 45302 | C7: IT | D7: Travel | E7: 9372.01 | F7: VEND-155
A8: EXP-500007 | B8: 45308 | C8: IT | D8: Operations | E8: 17872.04 | F8: VEND-104
A9: EXP-500008 | B9: 45309 | C9: IT | D9: Taxes | E9: 7163.76 | F9: VEND-146
A10: EXP-500009 | B10: 45304 | C10: IT | D10: Other | E10: 6963.31 | F10: VEND-121
A11: EXP-500010 | B11: 45317 | C11: HR | D11: Salaries | E11: 38877.17 | F11: VEND-156
A12: EXP-500011 | B12: 45293 | C12: HR | D12: Rent | E12: 9952.18 | F12: VEND-130
A13: EXP-500012 | B13: 45311 | C13: HR | D13: Utilities | E13: 3728.38 | F13: VEND-165
... A1513: EXP-501512 | B1513: 45996 | C1513: Sales | D1513: Other | E1513: 4003.91 | F1513: VEND-111

Sheet Budgets
A1: Month | B1: Department | C1: Category | D1: Budget
A2: 45292 | B2: Administration | C2: Operations | D2: 7172.8
A3: 45292 | B3: Administration | C3: Other | D3: 2287.23
A4: 45292 | B4: IT | C4: Salaries | D4: 103935.79
A5: 45292 | B5: IT | C5: Utilities | D5: 8702.9
A6: 45292 | B6: Operations | C6: Utilities | D6: 8807.78
A7: 45292 | B7: Administration | C7: Taxes | D7: 2500.19
A8: 45292 | B8: HR | C8: Rent | D8: 9395.31
A9: 45292 | B9: Marketing | C9: Rent | D9: 15466.21
A10: 45292 | B10: Marketing | C10: Travel | D10: 8146.36
A11: 45292 | B11: Operations | C11: Operations | D11: 18171.09
A12: 45292 | B12: Sales | C12: Rent | D12: 13269.64
A13: 45292 | B13: Administration | C13: Utilities | D13: 4152.17
... A1513: 45992 | B1513: Operations | C1513: Taxes | D1513: 5838.96

Sheet Customer_Master
A1: Customer_ID | B1: Customer_Name | C1: Segment | D1: Base_Risk
A2: CUST-001 | B2: Customer 001 | C2: SMB | D2: Medium
A3: CUST-002 | B3: Customer 002 | C3: SMB | D3: Low
A4: CUST-003 | B4: Customer 003 | C4: SMB | D4: Medium
A5: CUST-004 | B5: Customer 004 | C5: Mid-Market | D5: Medium
A6: CUST-005 | B6: Customer 005 | C6: SMB | D6: Low
A7: CUST-006 | B7: Customer 006 | C7: SMB | D7: High
A8: CUST-007 | B8: Customer 007 | C8: SMB | D8: Medium
A9: CUST-008 | B9: Customer 008 | C9: SMB | D9: Medium
A10: CUST-009 | B10: Customer 009 | C10: Enterprise | D10: Low
A11: CUST-010 | B11: Customer 010 | C11: SMB | D11: Low
A12: CUST-011 | B12: Customer 011 | C12: Enterprise | D12: Low
... A61: CUST-060 | B61: Customer 060 | C61: SMB | D61: Low

Sheet Revenue_Collections
A1: Invoice_Month | B1: Revenue | C1: Collected | D1: Outstanding | E1: Collection_Efficiency_% | F1: MoM_Revenue_Growth_%
A2: 45292 | B2: =SUMIFS(Clean_AR_Data!$F:$F,Clean_AR_Data!$C:$C,">="&A2,Clean_AR_Data!$C:$C,"<"&EDATE(A2,1)) -> 2685331 | C2: =SUMIFS(Clean_AR_Data!$G:$G,Clean_AR_Data!$E:$E,">="&A2,Clean_AR_Data!$E:$E,"<"&EDATE(A2,1)) -> 0 | D2: =SUMIFS(Clean_AR_Data!$H:$H,Clean_AR_Data!$C:$C,">="&A2,Clean_AR_Data!$C:$C,"<"&EDATE(A2,1)) -> 798551.31 | E2: =IFERROR(C2/B2,0) -> 0
A3: 45323 | B3: =SUMIFS(Clean_AR_Data!$F:$F,Clean_AR_Data!$C:$C,">="&A3,Clean_AR_Data!$C:$C,"<"&EDATE(A3,1)) -> 3604285.4 | C3: =SUMIFS(Clean_AR_Data!$G:$G,Clean_AR_Data!$E:$E,">="&A3,Clean_AR_Data!$E:$E,"<"&EDATE(A3,1)) -> 1498657.4 | D3: =SUMIFS(Clean_AR_Data!$H:$H,Clean_AR_Data!$C:$C,">="&A3,Clean_AR_Data!$C:$C,"<"&EDATE(A3,1)) -> 819364.98 | E3: =IFERROR(C3/B3,0) -> 0.41579877 | F3: 34.221271
A4: 45352 | B4: =SUMIFS(Clean_AR_Data!$F:$F,Clean_AR_Data!$C:$C,">="&A4,Clean_AR_Data!$C:$C,"<"&EDATE(A4,1)) -> 2936541.5 | C4: =SUMIFS(Clean_AR_Data!$G:$G,Clean_AR_Data!$E:$E,">="&A4,Clean_AR_Data!$E:$E,"<"&EDATE(A4,1)) -> 2156419.9 | D4: =SUMIFS(Clean_AR_Data!$H:$H,Clean_AR_Data!$C:$C,">="&A4,Clean_AR_Data!$C:$C,"<"&EDATE(A4,1)) -> 1067326.9 | E4: =IFERROR(C4/B4,0) -> 0.73434 | F4: -18.526388
A5: 45383 | B5: =SUMIFS(Clean_AR_Data!$F:$F,Clean_AR_Data!$C:$C,">="&A5,Clean_AR_Data!$C:$C,"<"&EDATE(A5,1)) -> 2893620.9 | C5: =SUMIFS(Clean_AR_Data!$G:$G,Clean_AR_Data!$E:$E,">="&A5,Clean_AR_Data!$E:$E,"<"&EDATE(A5,1)) -> 1818535 | D5: =SUMIFS(Clean_AR_Data!$H:$H,Clean_AR_Data!$C:$C,">="&A5,Clean_AR_Data!$C:$C,"<"&EDATE(A5,1)) -> 832177.61 | E5: =IFERROR(C5/B5,0) -> 0.62846347 | F5: -1.461602
A6: 45413 | B6: =SUMIFS(Clean_AR_Data!$F:$F,Clean_AR_Data!$C:$C,">="&A6,Clean_AR_Data!$C:$C,"<"&EDATE(A6,1)) -> 3452600.6 | C6: =SUMIFS(Clean_AR_Data!$G:$G,Clean_AR_Data!$E:$E,">="&A6,Clean_AR_Data!$E:$E,"<"&EDATE(A6,1)) -> 2217910.1 | D6: =SUMIFS(Clean_AR_Data!$H:$H,Clean_AR_Data!$C:$C,">="&A6,Clean_AR_Data!$C:$C,"<"&EDATE(A6,1)) -> 845354.09 | E6: =IFERROR(C6/B6,0) -> 0.64238826 | F6: 19.317654
A7: 45444 | B7: =SUMIFS(Clean_AR_Data!$F:$F,Clean_AR_Data!$C:$C,">="&A7,Clean_AR_Data!$C:$C,"<"&EDATE(A7,1)) -> 2919269.1 | C7: =SUMIFS(Clean_AR_Data!$G:$G,Clean_AR_Data!$E:$E,">="&A7,Clean_AR_Data!$E:$E,"<"&EDATE(A7,1)) -> 1754014.9 | D7: =SUMIFS(Clean_AR_Data!$H:$H,Clean_AR_Data!$C:$C,">="&A7,Clean_AR_Data!$C:$C,"<"&EDATE(A7,1)) -> 807622.7 | E7: =IFERROR(C7/B7,0) -> 0.60084043 | F7: -15.447242
A8: 45474 | B8: =SUMIFS(Clean_AR_Data!$F:$F,Clean_AR_Data!$C:$C,">="&A8,Clean_AR_Data!$C:$C,"<"&EDATE(A8,1)) -> 2254535.9 | C8: =SUMIFS(Clean_AR_Data!$G:$G,Clean_AR_Data!$E:$E,">="&A8,Clean_AR_Data!$E:$E,"<"&EDATE(A8,1)) -> 3112048.1 | D8: =SUMIFS(Clean_AR_Data!$H:$H,Clean_AR_Data!$C:$C,">="&A8,Clean_AR_Data!$C:$C,"<"&EDATE(A8,1)) -> 296119.25 | E8: =IFERROR(C8/B8,0) -> 1.3803498 | F8: -22.770535
A9: 45505 | B9: =SUMIFS(Clean_AR_Data!$F:$F,Clean_AR_Data!$C:$C,">="&A9,Clean_AR_Data!$C:$C,"<"&EDATE(A9,1)) -> 3024137.9 | C9: =SUMIFS(Clean_AR_Data!$G:$G,Clean_AR_Data!$E:$E,">="&A9,Clean_AR_Data!$E:$E,"<"&EDATE(A9,1)) -> 1617432.3 | D9: =SUMIFS(Clean_AR_Data!$H:$H,Clean_AR_Data!$C:$C,">="&A9,Clean_AR_Data!$C:$C,"<"&EDATE(A9,1)) -> 885006.64 | E9: =IFERROR(C9/B9,0) -> 0.53484079 | F9: 34.13572
A10: 45536 | B10: =SUMIFS(Clean_AR_Data!$F:$F,Clean_AR_Data!$C:$C,">="&A10,Clean_AR_Data!$C:$C,"<"&EDATE(A10,1)) -> 3423493.2 | C10: =SUMIFS(Clean_AR_Data!$G:$G,Clean_AR_Data!$E:$E,">="&A10,Clean_AR_Data!$E:$E,"<"&EDATE(A10,1)) -> 2296144.8 | D10: =SUMIFS(Clean_AR_Data!$H:$H,Clean_AR_Data!$C:$C,">="&A10,Clean_AR_Data!$C:$C,"<"&EDATE(A10,1)) -> 1056246.6 | E10: =IFERROR(C10/B10,0) -> 0.6707023 | F10: 13.205591
A11: 45566 | B11: =SUMIFS(Clean_AR_Data!$F:$F,Clean_AR_Data!$C:$C,">="&A11,Clean_AR_Data!$C:$C,"<"&EDATE(A11,1)) -> 3273949.7 | C11: =SUMIFS(Clean_AR_Data!$G:$G,Clean_AR_Data!$E:$E,">="&A11,Clean_AR_Data!$E:$E,"<"&EDATE(A11,1)) -> 1893766.4 | D11: =SUMIFS(Clean_AR_Data!$H:$H,Clean_AR_Data!$C:$C,">="&A11,Clean_AR_Data!$C:$C,"<"&EDATE(A11,1)) -> 899438.7 | E11: =IFERROR(C11/B11,0) -> 0.57843477 | F11: -4.3681561
A12: 45597 | B12: =SUMIFS(Clean_AR_Data!$F:$F,Clean_AR_Data!$C:$C,">="&A12,Clean_AR_Data!$C:$C,"<"&EDATE(A12,1)) -> 2784229.9 | C12: =SUMIFS(Clean_AR_Data!$G:$G,Clean_AR_Data!$E:$E,">="&A12,Clean_AR_Data!$E:$E,"<"&EDATE(A12,1)) -> 2599084.3 | D12: =SUMIFS(Clean_AR_Data!$H:$H,Clean_AR_Data!$C:$C,">="&A12,Clean_AR_Data!$C:$C,"<"&EDATE(A12,1)) -> 525078.5 | E12: =IFERROR(C12/B12,0) -> 0.93350204 | F12: -14.958072
A13: 45627 | B13: =SUMIFS(Clean_AR_Data!$F:$F,Clean_AR_Data!$C:$C,">="&A13,Clean_AR_Data!$C:$C,"<"&EDATE(A13,1)) -> 2513728.5 | C13: =SUMIFS(Clean_AR_Data!$G:$G,Clean_AR_Data!$E:$E,">="&A13,Clean_AR_Data!$E:$E,"<"&EDATE(A13,1)) -> 2048794.4 | D13: =SUMIFS(Clean_AR_Data!$H:$H,Clean_AR_Data!$C:$C,">="&A13,Clean_AR_Data!$C:$C,"<"&EDATE(A13,1)) -> 547106.34 | E13: =IFERROR(C13/B13,0) -> 0.81504203 | F13: -9.7154838
A14: 45658 | B14: =SUMIFS(Clean_AR_Data!$F:$F,Clean_AR_Data!$C:$C,">="&A14,Clean_AR_Data!$C:$C,"<"&EDATE(A14,1)) -> 2724300.6 | C14: =SUMIFS(Clean_AR_Data!$G:$G,Clean_AR_Data!$E:$E,">="&A14,Clean_AR_Data!$E:$E,"<"&EDATE(A14,1)) -> 2105588.5 | D14: =SUMIFS(Clean_AR_Data!$H:$H,Clean_AR_Data!$C:$C,">="&A14,Clean_AR_Data!$C:$C,"<"&EDATE(A14,1)) -> 871710.85 | E14: =IFERROR(C14/B14,0) -> 0.77289139 | F14: 8.3768819
... A25: 45992 | B25: =SUMIFS(Clean_AR_Data!$F:$F,Clean_AR_Data!$C:$C,">="&A25,Clean_AR_Data!$C:$C,"<"&EDATE(A25,1)) -> 3242803.2 | C25: =SUMIFS(Clean_AR_Data!$G:$G,Clean_AR_Data!$E:$E,">="&A25,Clean_AR_Data!$E:$E,"<"&EDATE(A25,1)) -> 2263449.7 | D25: =SUMIFS(Clean_AR_Data!$H:$H,Clean_AR_Data!$C:$C,">="&A25,Clean_AR_Data!$C:$C,"<"&EDATE(A25,1)) -> 822794.63 | E25: =IFERROR(C25/B25,0) -> 0.69799169 | F25: -16.979223

Sheet AR_Ageing
A1: Age_Bucket | B1: Outstanding | C1: Invoice_Count | D1: %_of_Total_AR
A2: 0-30 | B2: =SUMIFS(Clean_AR_Data!$H:$H,Clean_AR_Data!$L:$L,A2) -> 0 | C2: =COUNTIFS(Clean_AR_Data!$L:$L,A2) -> 0 | D2: =IFERROR(B2/SUM($B$2:$B$6),0) -> 0
A3: 31-60 | B3: =SUMIFS(Clean_AR_Data!$H:$H,Clean_AR_Data!$L:$L,A3) -> 0 | C3: =COUNTIFS(Clean_AR_Data!$L:$L,A3) -> 0 | D3: =IFERROR(B3/SUM($B$2:$B$6),0) -> 0
A4: 61-90 | B4: =SUMIFS(Clean_AR_Data!$H:$H,Clean_AR_Data!$L:$L,A4) -> 0 | C4: =COUNTIFS(Clean_AR_Data!$L:$L,A4) -> 0 | D4: =IFERROR(B4/SUM($B$2:$B$6),0) -> 0
A5: 91-120 | B5: =SUMIFS(Clean_AR_Data!$H:$H,Clean_AR_Data!$L:$L,A5) -> 0 | C5: =COUNTIFS(Clean_AR_Data!$L:$L,A5) -> 0 | D5: =IFERROR(B5/SUM($B$2:$B$6),0) -> 0
A6: 120+ | B6: =SUMIFS(Clean_AR_Data!$H:$H,Clean_AR_Data!$L:$L,A6) -> 0 | C6: =COUNTIFS(Clean_AR_Data!$L:$L,A6) -> 0 | D6: =IFERROR(B6/SUM($B$2:$B$6),0) -> 0

Sheet Customer_Risk
A1: Customer_ID | B1: Total_Invoiced | C1: Total_Collected | D1: Outstanding | E1: Avg_Payment_Delay | F1: Overdue_Invoices | G1: Invoice_Count | H1: Collection_Efficiency_% | I1: Risk_Score | J1: Risk_Class | K1: Customer_Name | L1: Segment
A2: CUST-006 | B2: 1254372.6 | C2: 307435.02 | D2: 946937.53 | E2: 336.93103 | F2: 20 | G2: 29 | H2: 24.509068 | I2: 95.098186 | J2: High | K2: Customer 006 | L2: SMB
A3: CUST-012 | B3: 1071011.4 | C3: 460539.27 | D3: 610472.16 | E3: 200.96154 | F3: 13 | G3: 26 | H3: 43.000407 | I3: 91.399919 | J3: High | K3: Customer 012 | L3: SMB
A4: CUST-030 | B4: 1314474.1 | C4: 742712.65 | D4: 571761.49 | E4: 197.88889 | F4: 14 | G4: 27 | H4: 56.502644 | I4: 88.699471 | J4: High | K4: Customer 030 | L4: SMB
A5: CUST-023 | B5: 846642.46 | C5: 330349.46 | D5: 516293 | E5: 199.41667 | F5: 14 | G5: 24 | H5: 39.018768 | I5: 87.97418 | J5: High | K5: Customer 023 | L5: Mid-Market
A6: CUST-032 | B6: 1507836.7 | C6: 833119.16 | D6: 674717.57 | E6: 178.75 | F6: 18 | G6: 36 | H6: 55.252611 | I6: 87.110158 | J6: High | K6: Customer 032 | L6: SMB
A7: CUST-008 | B7: 1321370.5 | C7: 670444.06 | D7: 650926.45 | E7: 173.85714 | F7: 14 | G7: 28 | H7: 50.738537 | I7: 87.105278 | J7: High | K7: Customer 008 | L7: SMB
A8: CUST-056 | B8: 1142424.4 | C8: 586020.61 | D8: 556403.81 | E8: 165.15385 | F8: 12 | G8: 26 | H8: 51.296226 | I8: 84.325127 | J8: High | K8: Customer 056 | L8: Mid-Market
A9: CUST-021 | B9: 1750160.7 | C9: 1163035.2 | D9: 587125.5 | E9: 143.37838 | F9: 15 | G9: 37 | H9: 66.453052 | I9: 78.308128 | J9: High | K9: Customer 021 | L9: SMB
A10: CUST-054 | B10: 749996.54 | C10: 383467.27 | D10: 366529.27 | E10: 199.68182 | F10: 11 | G10: 22 | H10: 51.129205 | I10: 73.723431 | J10: High | K10: Customer 054 | L10: SMB
A11: CUST-007 | B11: 1196416.9 | C11: 665216.03 | D11: 531200.82 | E11: 122.88889 | F11: 11 | G11: 27 | H11: 55.600691 | I11: 73.632893 | J11: High | K11: Customer 007 | L11: SMB
A12: CUST-055 | B12: 646060.39 | C12: 298330.29 | D12: 347730.1 | E12: 187.64706 | F12: 10 | G12: 17 | H12: 46.176843 | I12: 73.040316 | J12: High | K12: Customer 055 | L12: Enterprise
A13: CUST-046 | B13: 1582213 | C13: 1020573.1 | D13: 561639.95 | E13: 114.14286 | F13: 9 | G13: 35 | H13: 64.502887 | I13: 72.634088 | J13: High | K13: Customer 046 | L13: SMB
... A61: CUST-041 | B61: 837528.86 | C61: 837528.86 | D61: 0 | E61: 10.652174 | F61: 0 | G61: 23 | H61: 100 | I61: 1.9761305 | J61: Low | K61: Customer 041 | L61: Mid-Market

Sheet Budget_vs_Actual
A1: Month | B1: Department | C1: Category | D1: Budget | E1: Actual_Expense | F1: Variance | G1: Variance_% | H1: Budget_Status
A2: 45292 | B2: Administration | C2: Operations | D2: 7172.8 | E2: 6539.45 | F2: =E2-D2 -> -633.35 | G2: =IFERROR(F2/D2,0) -> -0.088298851 | H2: =IF(G2<=0,"Under Budget",IF(G2<=5%,"Within Budget",IF(G2<=15%,"Slightly Over","Significantly Over"))) -> Under Budget
A3: 45292 | B3: Administration | C3: Other | D3: 2287.23 | E3: 2480.19 | F3: =E3-D3 -> 192.96 | G3: =IFERROR(F3/D3,0) -> 0.084364056 | H3: =IF(G3<=0,"Under Budget",IF(G3<=5%,"Within Budget",IF(G3<=15%,"Slightly Over","Significantly Over"))) -> Slightly Over
A4: 45292 | B4: IT | C4: Salaries | D4: 103935.79 | E4: 95356.73 | F4: =E4-D4 -> -8579.06 | G4: =IFERROR(F4/D4,0) -> -0.082541923 | H4: =IF(G4<=0,"Under Budget",IF(G4<=5%,"Within Budget",IF(G4<=15%,"Slightly Over","Significantly Over"))) -> Under Budget
A5: 45292 | B5: IT | C5: Utilities | D5: 8702.9 | E5: 8620.85 | F5: =E5-D5 -> -82.05 | G5: =IFERROR(F5/D5,0) -> -0.0094278919 | H5: =IF(G5<=0,"Under Budget",IF(G5<=5%,"Within Budget",IF(G5<=15%,"Slightly Over","Significantly Over"))) -> Under Budget
A6: 45292 | B6: Operations | C6: Utilities | D6: 8807.78 | E6: 8858.25 | F6: =E6-D6 -> 50.47 | G6: =IFERROR(F6/D6,0) -> 0.0057301613 | H6: =IF(G6<=0,"Under Budget",IF(G6<=5%,"Within Budget",IF(G6<=15%,"Slightly Over","Significantly Over"))) -> Within Budget
A7: 45292 | B7: Administration | C7: Taxes | D7: 2500.19 | E7: 2475.08 | F7: =E7-D7 -> -25.11 | G7: =IFERROR(F7/D7,0) -> -0.010043237 | H7: =IF(G7<=0,"Under Budget",IF(G7<=5%,"Within Budget",IF(G7<=15%,"Slightly Over","Significantly Over"))) -> Under Budget
A8: 45292 | B8: HR | C8: Rent | D8: 9395.31 | E8: 9952.18 | F8: =E8-D8 -> 556.87 | G8: =IFERROR(F8/D8,0) -> 0.059271062 | H8: =IF(G8<=0,"Under Budget",IF(G8<=5%,"Within Budget",IF(G8<=15%,"Slightly Over","Significantly Over"))) -> Slightly Over
A9: 45292 | B9: Marketing | C9: Rent | D9: 15466.21 | E9: 15455.53 | F9: =E9-D9 -> -10.68 | G9: =IFERROR(F9/D9,0) -> -0.00069053763 | H9: =IF(G9<=0,"Under Budget",IF(G9<=5%,"Within Budget",IF(G9<=15%,"Slightly Over","Significantly Over"))) -> Under Budget
A10: 45292 | B10: Marketing | C10: Travel | D10: 8146.36 | E10: 7494.78 | F10: =E10-D10 -> -651.58 | G10: =IFERROR(F10/D10,0) -> -0.079984189 | H10: =IF(G10<=0,"Under Budget",IF(G10<=5%,"Within Budget",IF(G10<=15%,"Slightly Over","Significantly Over"))) -> Under Budget
A11: 45292 | B11: Operations | C11: Operations | D11: 18171.09 | E11: 16884.33 | F11: =E11-D11 -> -1286.76 | G11: =IFERROR(F11/D11,0) -> -0.070813584 | H11: =IF(G11<=0,"Under Budget",IF(G11<=5%,"Within Budget",IF(G11<=15%,"Slightly Over","Significantly Over"))) -> Under Budget
A12: 45292 | B12: Sales | C12: Rent | D12: 13269.64 | E12: 14178.92 | F12: =E12-D12 -> 909.28 | G12: =IFERROR(F12/D12,0) -> 0.068523336 | H12: =IF(G12<=0,"Under Budget",IF(G12<=5%,"Within Budget",IF(G12<=15%,"Slightly Over","Significantly Over"))) -> Slightly Over
A13: 45292 | B13: Administration | C13: Utilities | D13: 4152.17 | E13: 3961.42 | F13: =E13-D13 -> -190.75 | G13: =IFERROR(F13/D13,0) -> -0.045939834 | H13: =IF(G13<=0,"Under Budget",IF(G13<=5%,"Within Budget",IF(G13<=15%,"Slightly Over","Significantly Over"))) -> Under Budget
... A1513: 45992 | B1513: Operations | C1513: Taxes | D1513: 5838.96 | E1513: 5481.56 | F1513: =E1513-D1513 -> -357.4 | G1513: =IFERROR(F1513/D1513,0) -> -0.06120953 | H1513: =IF(G1513<=0,"Under Budget",IF(G1513<=5%,"Within Budget",IF(G1513<=15%,"Slightly Over","Significantly Over"))) -> Under Budget

Sheet Expense_Anomaly
A1: Expense_ID | B1: Expense_Date | C1: Department | D1: Category | E1: Actual_Expense | F1: Vendor_ID | G1: Group_Median | H1: Group_MAD | I1: Robust_Z | J1: IF_Anomaly | K1: Anomaly | L1: Variance_vs_Group_Median | M1: Risk_Level
A2: EXP-500001 | B2: 45292 | C2: IT | D2: Salaries | E2: 95356.73 | F2: VEND-121 | G2: 110154.51 | H2: 11029.19 | I2: -0.9049715 | J2: -1 | K2: Potential Anomaly | L2: -14797.78 | M2: Review
A3: EXP-500064 | B3: 45332 | C3: IT | D3: Salaries | E3: 94170.07 | F3: VEND-107 | G3: 110154.51 | H3: 11029.19 | I3: -0.97754276 | J3: -1 | K3: Potential Anomaly | L3: -15984.44 | M3: Review
A4: EXP-500100 | B4: 45338 | C4: Operations | D4: Salaries | E4: 99065 | F4: VEND-115 | G4: 86979.19 | H4: 8914.815 | I4: 0.91441929 | J4: -1 | K4: Potential Anomaly | L4: 12085.81 | M4: Review
A5: EXP-500127 | B5: 45362 | C5: IT | D5: Salaries | E5: 121526.2 | F5: VEND-145 | G5: 110154.51 | H5: 11029.19 | I5: 0.69544589 | J5: -1 | K5: Potential Anomaly | L5: 11371.69 | M5: Review
A6: EXP-500163 | B6: 45359 | C6: Operations | D6: Salaries | E6: 99503.55 | F6: VEND-147 | G6: 86979.19 | H6: 8914.815 | I6: 0.94760024 | J6: -1 | K6: Potential Anomaly | L6: 12524.36 | M6: Review
A7: EXP-500190 | B7: 45397 | C7: IT | D7: Salaries | E7: 125268.93 | F7: VEND-131 | G7: 110154.51 | H7: 11029.19 | I7: 0.9243359 | J7: -1 | K7: Potential Anomaly | L7: 15114.42 | M7: Review
A8: EXP-500217 | B8: 45391 | C8: Marketing | D8: Salaries | E8: 93521.11 | F8: VEND-117 | G8: 73087.9 | H8: 5096.99 | I8: 2.7039881 | J8: -1 | K8: Potential Anomaly | L8: 20433.21 | M8: Review
A9: EXP-500253 | B9: 45428 | C9: IT | D9: Salaries | E9: 132803.43 | F9: VEND-169 | G9: 110154.51 | H9: 11029.19 | I9: 1.385115 | J9: -1 | K9: Potential Anomaly | L9: 22648.92 | M9: Review
A10: EXP-500289 | B10: 45421 | C10: Operations | D10: Salaries | E10: 108214.3 | F10: VEND-176 | G10: 86979.19 | H10: 8914.815 | I10: 1.6066606 | J10: -1 | K10: Potential Anomaly | L10: 21235.11 | M10: Review
A11: EXP-500316 | B11: 45470 | C11: IT | D11: Salaries | E11: 121631.34 | F11: VEND-148 | G11: 110154.51 | H11: 11029.19 | I11: 0.70187583 | J11: -1 | K11: Potential Anomaly | L11: 11476.83 | M11: Review
A12: EXP-500379 | B12: 45491 | C12: IT | D12: Salaries | E12: 106828.19 | F12: VEND-111 | G12: 110154.51 | H12: 11029.19 | I12: -0.20342408 | J12: -1 | K12: Potential Anomaly | L12: -3326.32 | M12: Review
A13: EXP-500442 | B13: 45520 | C13: IT | D13: Salaries | E13: 99805.33 | F13: VEND-158 | G13: 110154.51 | H13: 11029.19 | I13: -0.63291338 | J13: -1 | K13: Potential Anomaly | L13: -10349.18 | M13: Review
... A36: EXP-501450 | B36: 46002 | C36: IT | D36: Salaries | E36: 113559.73 | F36: VEND-128 | G36: 110154.51 | H36: 11029.19 | I36: 0.20824928 | J36: -1 | K36: Potential Anomaly | L36: 3405.22 | M36: Review

Sheet Cash_Flow
A1: Month | B1: Collections | C1: Other_Income | D1: Cash_Inflows | E1: Cash_Outflows | F1: Net_Cash_Flow | G1: Opening_Cash | H1: Closing_Cash
A2: 45292 | B2: 0 | C2: 0 | D2: 0 | E2: 892257.08 | F2: =D2-E2 -> -892257.08 | G2: 2500000 | H2: =G2+F2 -> 1607742.9
A3: 45323 | B3: 1498657.4 | C3: 23540.173 | D3: 1522197.6 | E3: 952090.14 | F3: =D3-E3 -> 570107.46 | G3: =H2 -> 1607742.9 | H3: =G3+F3 -> 2177850.4
A4: 45352 | B4: 2156419.9 | C4: 71414.733 | D4: 2227834.6 | E4: 1005827.9 | F4: =D4-E4 -> 1222006.7 | G4: =H3 -> 2177850.4 | H4: =G4+F4 -> 3399857
A5: 45383 | B5: 1818535.1 | C5: 59150.341 | D5: 1877685.4 | E5: 1021078.5 | F5: =D5-E5 -> 856606.89 | G5: =H4 -> 3399857 | H5: =G5+F5 -> 4256463.9
A6: 45413 | B6: 2217910.1 | C6: 41466.89 | D6: 2259377 | E6: 999020.26 | F6: =D6-E6 -> 1260356.7 | G6: =H5 -> 4256463.9 | H6: =G6+F6 -> 5516820.7
A7: 45444 | B7: 1754014.9 | C7: 35618.52 | D7: 1789633.4 | E7: 972648.57 | F7: =D7-E7 -> 816984.84 | G7: =H6 -> 5516820.7 | H7: =G7+F7 -> 6333805.5
A8: 45474 | B8: 3112048.1 | C8: 58416.726 | D8: 3170464.8 | E8: 924314.79 | F8: =D8-E8 -> 2246150 | G8: =H7 -> 6333805.5 | H8: =G8+F8 -> 8579955.6
A9: 45505 | B9: 1617432.3 | C9: 47537.453 | D9: 1664969.8 | E9: 843246.09 | F9: =D9-E9 -> 821723.67 | G9: =H8 -> 8579955.6 | H9: =G9+F9 -> 9401679.2
A10: 45536 | B10: 2296144.8 | C10: 45923.303 | D10: 2342068.1 | E10: 853380.45 | F10: =D10-E10 -> 1488687.6 | G10: =H9 -> 9401679.2 | H10: =G10+F10 -> 10890367
A11: 45566 | B11: 1893766.4 | C11: 63685.459 | D11: 1957451.8 | E11: 844573.46 | F11: =D11-E11 -> 1112878.3 | G11: =H10 -> 10890367 | H11: =G11+F11 -> 12003245
A12: 45597 | B12: 2599084.3 | C12: 82008.442 | D12: 2681092.8 | E12: 853375.48 | F12: =D12-E12 -> 1827717.3 | G12: =H11 -> 12003245 | H12: =G12+F12 -> 13830963
A13: 45627 | B13: 2048794.4 | C13: 54842.175 | D13: 2103636.6 | E13: 877812.08 | F13: =D13-E13 -> 1225824.5 | G13: =H12 -> 13830963 | H13: =G13+F13 -> 15056787
A14: 45658 | B14: 2105588.5 | C14: 31960.232 | D14: 2137548.7 | E14: 918898.23 | F14: =D14-E14 -> 1218650.5 | G14: =H13 -> 15056787 | H14: =G14+F14 -> 16275437
... A25: 45992 | B25: 2263449.7 | C25: 65698.333 | D25: 2329148 | E25: 895190.78 | F25: =D25-E25 -> 1433957.2 | G25: =H24 -> 29979181 | H25: =G25+F25 -> 31413139

Sheet Cash_Forecast
A1: Month | B1: Expected_Collections | C1: Forecast_Expenses | D1: Base_Net_Cash_Flow | E1: Base_Closing_Cash | F1: Stress_Net_Cash_Flow | G1: Stress_Closing_Cash | H1: Optimistic_Net_Cash_Flow | I1: Optimistic_Closing_Cash
A2: 46023 | B2: 2130761.3 | C2: 868671.59 | D2: 1262089.7 | E2: 32675228 | F2: 855608.35 | G2: 32268747 | H2: 1561214.6 | I2: 32974353
A3: 46054 | B3: 2130761.3 | C3: 868671.59 | D3: 1262089.7 | E3: 33937318 | F3: 855608.35 | G3: 33124355 | H3: 1561214.6 | I3: 34535568
A4: 46082 | B4: 2130761.3 | C4: 868671.59 | D4: 1262089.7 | E4: 35199408 | F4: 855608.35 | G4: 33979964 | H4: 1561214.6 | I4: 36096782
A5: 46113 | B5: 2130761.3 | C5: 868671.59 | D5: 1262089.7 | E5: 36461497 | F5: 855608.35 | G5: 34835572 | H5: 1561214.6 | I5: 37657997
A6: 46143 | B6: 2130761.3 | C6: 868671.59 | D6: 1262089.7 | E6: 37723587 | F6: 855608.35 | G6: 35691180 | H6: 1561214.6 | I6: 39219212
A7: 46174 | B7: 2130761.3 | C7: 868671.59 | D7: 1262089.7 | E7: 38985677 | F7: 855608.35 | G7: 36546789 | H7: 1561214.6 | I7: 40780426

Sheet KPI_Summary
A1: Metric | B1: Value
A2: Receivable Days | B2: =IFERROR(SUM(Clean_AR_Data!$H:$H)/(SUM(Clean_AR_Data!$F:$F)/365),0) -> 91.664226
A3: Payable Days | B3: 42
A4: Inventory Days | B4: 18
A5: Cash Conversion Cycle | B5: =B2+B3-B4 -> 115.66423
A6: Collection Efficiency % | B6: 74.886513
A7: Overdue AR | B7: 17303752
A8: Closing Cash | B8: 31413139
A9: Budget Overrun % | B9: 0
A10: Negative Cash Flow Months | B10: 1
A11: Liquidity Risk Score | B11: =MIN(100,ROUND((B2>90)*35+(B2>60)*(B2<=90)*25+(B7>0)*(B7/SUM(Clean_AR_Data!$H:$H)>30%)*25+(B6<70%)*20,0)) -> 60
A12: Liquidity Risk Level | B12: =IF(B11>=70,"High",IF(B11>=40,"Medium","Low")) -> Medium

Sheet Expense_Analysis
A1: EXPENSE ANALYSIS ENGINE | P1: Departments | Q1: Categories | R1: Months
P2: department | Q2: Category
A3: MONTHLY EXPENSE TREND | E3: CATEGORY-WISE EXPENSE | I3: DEPARTMENT-WISE EXPENSE | P3: Administration | Q3: Marketing | R3: 45292
A4: Month | B4: Expense | C4: MoM Growth | E4: Category | F4: Expense | G4: % Total | I4: Department | J4: Expense | K4: % Total | P4: Finance | Q4: Operations | R4: 45323
A5: =DATE(YEAR(MIN(Clean_Expenses!$B:$B)),1,1) -> 45292 | B5: =IF(OR(Dashboard!$D$4="All Months",TEXT(A5,"mmm-yy")=TEXT(Dashboard!$D$4,"mmm-yy")),SUMIFS(Clean_Expenses!$E:$E,Clean_Expenses!$B:$B,">="&A5,Clean_Expenses!$B:$B,"<"&EDATE(A5,1)),0) -> 0 | C5: ="" | E5: Marketing | F5: =IF(OR(Dashboard!$J$4="All Categories",E5=Dashboard!$J$4),SUMIFS(Clean_Expenses!$E:$E,Clean_Expenses!$D:$D,E5),0) -> 1779638 | G5: =IFERROR(F5/SUM($F$5:$F$13),0) -> 0.080713668 | I5: Administration | J5: =IF(OR(Dashboard!$G$4="All Departments",I5=Dashboard!$G$4),SUMIFS(Clean_Expenses!$E:$E,Clean_Expenses!$C:$C,I5),0) -> 2027783.9 | K5: =IFERROR(J5/SUM($J$5:$J$11),0) -> 0.09196807 | P5: HR | Q5: Other | R5: 45352
A6: =DATE(YEAR(MIN(Clean_Expenses!$B:$B)),2,1) -> 45323 | B6: =IF(OR(Dashboard!$D$4="All Months",TEXT(A6,"mmm-yy")=TEXT(Dashboard!$D$4,"mmm-yy")),SUMIFS(Clean_Expenses!$E:$E,Clean_Expenses!$B:$B,">="&A6,Clean_Expenses!$B:$B,"<"&EDATE(A6,1)),0) -> 0 | C6: =IFERROR(B6/B5-1,0) -> 0 | E6: Operations | F6: =IF(OR(Dashboard!$J$4="All Categories",E6=Dashboard!$J$4),SUMIFS(Clean_Expenses!$E:$E,Clean_Expenses!$D:$D,E6),0) -> 1754240.3 | G6: =IFERROR(F6/SUM($F$5:$F$13),0) -> 0.079561779 | I6: Finance | J6: =IF(OR(Dashboard!$G$4="All Departments",I6=Dashboard!$G$4),SUMIFS(Clean_Expenses!$E:$E,Clean_Expenses!$C:$C,I6),0) -> 1814899.1 | K6: =IFERROR(J6/SUM($J$5:$J$11),0) -> 0.082312898 | P6: IT | Q6: Rent | R6: 45383
A7: =DATE(YEAR(MIN(Clean_Expenses!$B:$B)),3,1) -> 45352 | B7: =IF(OR(Dashboard!$D$4="All Months",TEXT(A7,"mmm-yy")=TEXT(Dashboard!$D$4,"mmm-yy")),SUMIFS(Clean_Expenses!$E:$E,Clean_Expenses!$B:$B,">="&A7,Clean_Expenses!$B:$B,"<"&EDATE(A7,1)),0) -> 0 | C7: =IFERROR(B7/B6-1,0) -> 0 | E7: Other | F7: =IF(OR(Dashboard!$J$4="All Categories",E7=Dashboard!$J$4),SUMIFS(Clean_Expenses!$E:$E,Clean_Expenses!$D:$D,E7),0) -> 657455.58 | G7: =IFERROR(F7/SUM($F$5:$F$13),0) -> 0.029818227 | I7: HR | J7: =IF(OR(Dashboard!$G$4="All Departments",I7=Dashboard!$G$4),SUMIFS(Clean_Expenses!$E:$E,Clean_Expenses!$C:$C,I7),0) -> 2190418 | K7: =IFERROR(J7/SUM($J$5:$J$11),0) -> 0.099344173 | P7: Marketing | Q7: Salaries | R7: 45413
A8: =DATE(YEAR(MIN(Clean_Expenses!$B:$B)),4,1) -> 45383 | B8: =IF(OR(Dashboard!$D$4="All Months",TEXT(A8,"mmm-yy")=TEXT(Dashboard!$D$4,"mmm-yy")),SUMIFS(Clean_Expenses!$E:$E,Clean_Expenses!$B:$B,">="&A8,Clean_Expenses!$B:$B,"<"&EDATE(A8,1)),0) -> 0 | C8: =IFERROR(B8/B7-1,0) -> 0 | E8: Rent | F8: =IF(OR(Dashboard!$J$4="All Categories",E8=Dashboard!$J$4),SUMIFS(Clean_Expenses!$E:$E,Clean_Expenses!$D:$D,E8),0) -> 2184651.6 | G8: =IFERROR(F8/SUM($F$5:$F$13),0) -> 0.099082643 | I8: IT | J8: =IF(OR(Dashboard!$G$4="All Departments",I8=Dashboard!$G$4),SUMIFS(Clean_Expenses!$E:$E,Clean_Expenses!$C:$C,I8),0) -> 5119961.5 | K8: =IFERROR(J8/SUM($J$5:$J$11),0) -> 0.23221063 | P8: Operations | Q8: Software | R8: 45444
A9: =DATE(YEAR(MIN(Clean_Expenses!$B:$B)),5,1) -> 45413 | B9: =IF(OR(Dashboard!$D$4="All Months",TEXT(A9,"mmm-yy")=TEXT(Dashboard!$D$4,"mmm-yy")),SUMIFS(Clean_Expenses!$E:$E,Clean_Expenses!$B:$B,">="&A9,Clean_Expenses!$B:$B,"<"&EDATE(A9,1)),0) -> 0 | C9: =IFERROR(B9/B8-1,0) -> 0 | E9: Salaries | F9: =IF(OR(Dashboard!$J$4="All Categories",E9=Dashboard!$J$4),SUMIFS(Clean_Expenses!$E:$E,Clean_Expenses!$D:$D,E9),0) -> 11074963 | G9: =IFERROR(F9/SUM($F$5:$F$13),0) -> 0.50229366 | I9: Marketing | J9: =IF(OR(Dashboard!$G$4="All Departments",I9=Dashboard!$G$4),SUMIFS(Clean_Expenses!$E:$E,Clean_Expenses!$C:$C,I9),0) -> 3519337.4 | K9: =IFERROR(J9/SUM($J$5:$J$11),0) -> 0.15961596 | P9: Sales | Q9: Taxes | R9: 45474
A10: =DATE(YEAR(MIN(Clean_Expenses!$B:$B)),6,1) -> 45444 | B10: =IF(OR(Dashboard!$D$4="All Months",TEXT(A10,"mmm-yy")=TEXT(Dashboard!$D$4,"mmm-yy")),SUMIFS(Clean_Expenses!$E:$E,Clean_Expenses!$B:$B,">="&A10,Clean_Expenses!$B:$B,"<"&EDATE(A10,1)),0) -> 0 | C10: =IFERROR(B10/B9-1,0) -> 0 | E10: Software | F10: =IF(OR(Dashboard!$J$4="All Categories",E10=Dashboard!$J$4),SUMIFS(Clean_Expenses!$E:$E,Clean_Expenses!$D:$D,E10),0) -> 1760247 | G10: =IFERROR(F10/SUM($F$5:$F$13),0) -> 0.079834208 | I10: Operations | J10: =IF(OR(Dashboard!$G$4="All Departments",I10=Dashboard!$G$4),SUMIFS(Clean_Expenses!$E:$E,Clean_Expenses!$C:$C,I10),0) -> 4236564.5 | K10: =IFERROR(J10/SUM($J$5:$J$11),0) -> 0.19214506 | Q10: Travel | R10: 45505
A11: =DATE(YEAR(MIN(Clean_Expenses!$B:$B)),7,1) -> 45474 | B11: =IF(OR(Dashboard!$D$4="All Months",TEXT(A11,"mmm-yy")=TEXT(Dashboard!$D$4,"mmm-yy")),SUMIFS(Clean_Expenses!$E:$E,Clean_Expenses!$B:$B,">="&A11,Clean_Expenses!$B:$B,"<"&EDATE(A11,1)),0) -> 924314.79 | C11: =IFERROR(B11/B10-1,0) -> 0 | E11: Taxes | F11: =IF(OR(Dashboard!$J$4="All Categories",E11=Dashboard!$J$4),SUMIFS(Clean_Expenses!$E:$E,Clean_Expenses!$D:$D,E11),0) -> 659136.8 | G11: =IFERROR(F11/SUM($F$5:$F$13),0) -> 0.029894477 | I11: Sales | J11: =IF(OR(Dashboard!$G$4="All Departments",I11=Dashboard!$G$4),SUMIFS(Clean_Expenses!$E:$E,Clean_Expenses!$C:$C,I11),0) -> 3139817.2 | K11: =IFERROR(J11/SUM($J$5:$J$11),0) -> 0.14240321 | Q11: Utilities | R11: 45536
A12: =DATE(YEAR(MIN(Clean_Expenses!$B:$B)),8,1) -> 45505 | B12: =IF(OR(Dashboard!$D$4="All Months",TEXT(A12,"mmm-yy")=TEXT(Dashboard!$D$4,"mmm-yy")),SUMIFS(Clean_Expenses!$E:$E,Clean_Expenses!$B:$B,">="&A12,Clean_Expenses!$B:$B,"<"&EDATE(A12,1)),0) -> 0 | C12: =IFERROR(B12/B11-1,0) -> -1 | E12: Travel | F12: =IF(OR(Dashboard!$J$4="All Categories",E12=Dashboard!$J$4),SUMIFS(Clean_Expenses!$E:$E,Clean_Expenses!$D:$D,E12),0) -> 1071176.4 | G12: =IFERROR(F12/SUM($F$5:$F$13),0) -> 0.048582111 | R12: 45566
A13: =DATE(YEAR(MIN(Clean_Expenses!$B:$B)),9,1) -> 45536 | B13: =IF(OR(Dashboard!$D$4="All Months",TEXT(A13,"mmm-yy")=TEXT(Dashboard!$D$4,"mmm-yy")),SUMIFS(Clean_Expenses!$E:$E,Clean_Expenses!$B:$B,">="&A13,Clean_Expenses!$B:$B,"<"&EDATE(A13,1)),0) -> 0 | C13: =IFERROR(B13/B12-1,0) -> 0 | E13: Utilities | F13: =IF(OR(Dashboard!$J$4="All Categories",E13=Dashboard!$J$4),SUMIFS(Clean_Expenses!$E:$E,Clean_Expenses!$D:$D,E13),0) -> 1107272.8 | G13: =IFERROR(F13/SUM($F$5:$F$13),0) -> 0.050219229 | R13: 45597
A14: =DATE(YEAR(MIN(Clean_Expenses!$B:$B)),10,1) -> 45566 | B14: =IF(OR(Dashboard!$D$4="All Months",TEXT(A14,"mmm-yy")=TEXT(Dashboard!$D$4,"mmm-yy")),SUMIFS(Clean_Expenses!$E:$E,Clean_Expenses!$B:$B,">="&A14,Clean_Expenses!$B:$B,"<"&EDATE(A14,1)),0) -> 0 | C14: =IFERROR(B14/B13-1,0) -> 0 | R14: 45627
A15: =DATE(YEAR(MIN(Clean_Expenses!$B:$B)),11,1) -> 45597 | B15: =IF(OR(Dashboard!$D$4="All Months",TEXT(A15,"mmm-yy")=TEXT(Dashboard!$D$4,"mmm-yy")),SUMIFS(Clean_Expenses!$E:$E,Clean_Expenses!$B:$B,">="&A15,Clean_Expenses!$B:$B,"<"&EDATE(A15,1)),0) -> 0 | C15: =IFERROR(B15/B14-1,0) -> 0
A16: =DATE(YEAR(MIN(Clean_Expenses!$B:$B)),12,1) -> 45627 | B16: =IF(OR(Dashboard!$D$4="All Months",TEXT(A16,"mmm-yy")=TEXT(Dashboard!$D$4,"mmm-yy")),SUMIFS(Clean_Expenses!$E:$E,Clean_Expenses!$B:$B,">="&A16,Clean_Expenses!$B:$B,"<"&EDATE(A16,1)),0) -> 0 | C16: =IFERROR(B16/B15-1,0) -> 0

Sheet Dashboard_Lists
A1: Month List | B1: Department List | C1: Category List
A2: All Months | B2: All Departments | C2: All Categories
A3: 45292 | B3: Administration | C3: Marketing
A4: 45323 | B4: Finance | C4: Operations
A5: 45352 | B5: HR | C5: Other
A6: 45383 | B6: IT | C6: Rent
A7: 45413 | B7: Marketing | C7: Salaries
A8: 45444 | B8: Operations | C8: Software
A9: 45474 | B9: Sales | C9: Taxes
A10: 45505 | C10: Travel
A11: 45536 | C11: Utilities
A12: 45566
A13: 45597
A14: 45627
A15: 45658
A16: 45689
A17: 45717
A18: 45748
A19: 45778
A20: 45809
A21: 45839
A22: 45870
A23: 45901
... A26: 45992
